Workbook

Sheet רשימת בקשות לעבור עליהם
A1: request_number | B1: flag | C1: city | D1: project_id | E1: project_name | F1: project_gush_helka | G1: project_migrash | H1: נבדק? | I1: האם הבקשה שויכה לפרויקט הנכון? | J1: הערות | K1: מזהה פרויקט חדש | L1: project_sug_bnia | M1: match_method | N1: db_status | O1: scraped_status | P1: scraped_status_date | Q1: type_confirmed | R1: request_date | S1: request_category | T1: full_address | U1: request_type | V1: shimush_ikari | W1: unit_count | X1: manual_review_event | Y1: bakasha_description | Z1: requestor | AA1: permit_block_lot | AB1: permit_migrash | AC1: request_url
A2: 20160086 | B2: status_advanced | C2: אשקלון | D2: גרופית_באגמים | E2: טופ אגמים - אשקלון | F2: 2886-8 , 2886-9 , 2886-10 | G2: 120/101/02/4+307 , 120/101/02/4+402 , 120/101/02/4+403 | H2: TRUE | I2: TRUE | L2: בניה חדשה | M2: gush_helka | N2: היתר בניה | O2: טופס 4 | P2: 27/10/2022 | Q2: TRUE | R2: 42402 | S2: בקשה להיתר | T2: מפל התנור 10 אשקלון | U2: בניה חדשה רוויה | V2: מגורים חדש -רוויה | W2: 116 | Z2: גרופית נכסים והנדסה(1993)בע"מ | AA2: 360405 | AB2: 403
A3: 20160462 | B3: status_advanced | C3: אשקלון | D3: אגמים_אשקלון | E3: אגמים אשקלון | F3: 358852 | G3: 120/101/02/4+200 | H3: TRUE | I3: TRUE | L3: בניה חדשה | M3: gush_helka | N3: היתר בניה | O3: טופס 4 | P3: 43474 | Q3: TRUE | R3: 15/03/2016 | S3: בקשה להיתר | T3: שד' עמק יזרעאל 3 אשקלון | U3: בניה חדשה רוויה | V3: מגורים חדש -רוויה | W3: 33 | Z3: רונידן חב' לבנין בע"מ | AA3: 358852 | AB3: 200
A4: 20160463 | B4: status_advanced | C4: אשקלון | D4: אגמים_אשקלון | E4: אגמים אשקלון | F4: 358852 | G4: 120/101/02/4+200 | H4: TRUE | I4: TRUE | L4: בניה חדשה | M4: gush_helka | N4: היתר בניה | O4: טופס 4 | P4: 31/07/2022 | Q4: TRUE | R4: 15/03/2016 | S4: בקשה להיתר | T4: נחל פרת 3 אשקלון | U4: בניה חדשה רוויה | V4: מגורים חדש -רוויה | W4: 27 | Z4: אבי נמני הנדסה ובנין בע"מ | AA4: 358852 | AB4: 200
A5: 20190022 | B5: status_advanced | C5: אשקלון | D5: ליאם_נחמיאס_אשקלון__מתחם_1 | E5: ליאם נחמיאס בבלוט מתחם א אשקלון | F5: 1967-15 , 1967-47 , 2950-10 | G5: 192/03/4+1 | H5: TRUE | I5: TRUE | L5: בניה חדשה | M5: gush_helka | N5: היתר בניה | O5: טופס 4 | P5: 29/10/2023 | Q5: TRUE | R5: 13/01/2019 | S5: בקשה להיתר הקלות/ש.חורג | T5: שד' אריה תגר 15 אשקלון | U5: בניה חדשה רוויה | V5: בנייה רוויה דיור למשתכן | W5: 73 | Z5: ליאם נחמיאס חב' לבנין בע"מ | AA5: 383780 | AB5: 1
A6: 20200787 | B6: status_advanced | C6: אשקלון | D6: כ_כוכב_הנגב_בבלוט_ח | E6: כ.כוכב הנגב בבלוט מתחם ב' | F6: 1967-16 , 1967-17 , 2950-48 | G6: 192/03/4+14 | H6: TRUE | I6: TRUE | L6: בניה חדשה | M6: gush_helka | N6: היתר בניה | O6: טופס 4 | P6: 18/03/2026 | Q6: TRUE | R6: 29/10/2018 | S6: בקשה להיתר | T6: זהבון 3 אשקלון | U6: בניה חדשה רוויה | V6: בנייה רוויה דיור למשתכן | W6: 133 | Z6: כ.כוכב הנגב חב' לבנין ופתוח (1990) בע"מ | AA6: 2950-48 | AB6: 14
A7: 20200813 | B7: status_advanced | C7: אשקלון | D7: הרב_דוד_בוזגלו_69-73-76-78_אשקלון | E7: אחוזת אפרידר | F7: 1966-402 , 1966-403 , 1966-404 , 1966-405 | H7: TRUE | I7: TRUE | L7: בניה חדשה | M7: gush_helka | N7: היתר בניה | O7: טופס 4 | P7: 20/08/2025 | Q7: TRUE | R7: 29/11/2020 | S7: בקשה להיתר | T7: הרב דוד בוזגלו 73 אשקלון | U7: בניה חדשה | V7: מבני ציבור | W7: 38 | Z7: אפרידר החברה לשכון ופתוח ישראל בע"מ | AA7: 1966-404 | AB7: 1503
A8: 20200814 | B8: status_advanced | C8: אשקלון | D8: הרב_דוד_בוזגלו_69-73-76-78_אשקלון | E8: אחוזת אפרידר | F8: 1966-402 , 1966-403 , 1966-404 , 1966-405 | H8: TRUE | I8: TRUE | L8: בניה חדשה | M8: gush_helka | N8: היתר בניה | O8: טופס 4 | P8: 30/12/2025 | Q8: TRUE | R8: 29/11/2020 | S8: בקשה להיתר | T8: הרב דוד בוזגלו 69 אשקלון | U8: בניה חדשה | V8: מבני ציבור | W8: 66 | Z8: אפרידר החברה לשכון ופתוח ישראל בע"מ | AA8: 1966-405 | AB8: 1504
A9: 20210732 | B9: status_advanced | C9: אשקלון | D9: אשקלון_מתחם_44_מגרש_305 | E9: ליאם נחמיאס בעיר היין, מתחם 44, אשקלון | F9: 369-52 , 369-63 , 369-71 , 369-72 , 369-76 | G9: תמל/1006+305 | H9: TRUE | I9: TRUE | L9: בניה חדשה | M9: gush_helka | N9: היתר בניה | O9: טופס 4 | P9: 21/06/2026 | Q9: TRUE | R9: 19/10/2021 | S9: בקשה להיתר הקלות/ש.חורג | T9: דרך ארץ 34 אשקלון | U9: בניה חדשה רוויה | V9: בנייה רוויה דיור למשתכן | W9: 180 | Z9: ליאם נחמיאס חב' לבנין בע"מ | AA9: 369-71 | AB9: 305
A10: 20210746 | B10: status_advanced | C10: אשקלון | D10: מגרש_203_214_אגמים_מזרח_אשקלון | E10: אביסרור באגמים הירוקה, אשקלון | F10: 1474-61 , 1474-68 , 1474-71 , 1475-58 , 1476-67 | G10: תמל/1022+203 , תמל/1022+214 | H10: TRUE | I10: TRUE | L10: בניה חדשה | M10: gush_helka | N10: היתר בניה | O10: טופס 4 | P10: 17/02/2025 | Q10: TRUE | R10: 26/10/2021 | S10: בקשה להיתר הקלות/ש.חורג | T10: נופר 1 אשקלון | U10: בניה חדשה רוויה | V10: בנייה רוויה דיור למשתכן | W10: 24 | Z10: אביסרור משה ובניו עבודות בנין ופתוח בע"מ | AA10: 1475-58 | AB10: 203
A11: 20220304 | B11: status_advanced | C11: אשקלון | D11: מתחם_71403_עיר_היין_אשקלון | E11: קבוצת נמיר נדל"ן במגרש 3 עיר היין אשקלון | F11: 362-88 , 363-60 | G11: תמל/1006+3 | H11: TRUE | I11: TRUE | L11: בניה חדשה | M11: gush_helka | N11: היתר בניה | O11: טופס 4 | P11: 45813 | Q11: TRUE | R11: 28/04/2022 | S11: בקשה להיתר הקלות/ש.חורג | T11: היינן 33 אשקלון | U11: בניה חדשה רוויה | V11: בנייה רוויה דיור למשתכן | W11: 90 | Z11: נמיר בעיר היין בע"מ | AA11: 362-88 | AB11: 3
A12: 20230313 | B12: status_advanced | C12: אשקלון | D12: הרב_בוזגלו_דוד_69_אשקלון | E12: הרב בוזגלו דוד 69 אשקלון | F12: 1966-396 | H12: TRUE | I12: TRUE | L12: בניה חדשה | M12: gush_helka | N12: היתר בתנאים | O12: היתר | P12: 25/03/2026 | Q12: TRUE | R12: 16/05/2024 | S12: בקשה להיתר הקלות/ש.חורג | T12: הרב דוד בוזגלו 71 אשקלון | U12: בניה חדשה רוויה | V12: מגורים חדש -רוויה | W12: 16 | Z12: ש.מ. חופית הנדסה ובניה בע"מ | AA12: 1966-396 | AB12: 396
A13: 20230593 | B13: status_advanced | C13: אשקלון | D13: הרב_בוזגלו_דוד_26_אשקלון | E13: הרב בוזגלו דוד 26 אשקלון | F13: 1936-348 | H13: TRUE | I13: TRUE | L13: בניה חדשה | M13: gush_helka | N13: היתר בתנאים | O13: היתר | P13: 25/02/2026 | Q13: TRUE | R13: 45993 | S13: בקשה להיתר הקלות/ש.חורג | T13: הרב דוד בוזגלו 26 אשקלון | U13: בניה חדשה | V13: מסחר/משרדים | Z13: וואסט מ.ל נכסים 2006 בע"מ | AA13: 1936-348 | AB13: 1102
A14: 20230759 | B14: status_advanced | C14: אשקלון | D14: מגרש_110_אבן_עזרא_אשקלון | E14: אבני חושן | F14: 1197-87 , 1197-89 , 1197-90 , 1197-91 , 1197-92 , 1197-93 , 1197-95 , 1197-100 | G14: תמל/1048+108 , תמל/1048+110 | H14: TRUE | I14: TRUE | L14: בניה חדשה | M14: gush_helka | N14: היתר בניה | O14: טופס 4 | P14: 23/06/2026 | Q14: TRUE | R14: 45211 | S14: בקשה להיתר הקלות/ש.חורג | T14: הרב יוסף שרביט 5 אשקלון | U14: בניה חדשה רוויה | V14: בנייה רוויה דיור למשתכן | W14: 102 | Z14: א.ד.מ. בוני ישראל יזמות ובניה בע"מ | AA14: 1197-87 | AB14: 108
A15: 20250262 | B15: status_advanced | C15: אשקלון | D15: מגרש_13_בעיר_היין_אשקלון | E15: מגרש 13 בעיר היין אשקלון | F15: 362-93 , 362-94 , 362-95 , 362-98 , 369-58 , 369-59 | G15: תמל/1006+13 | H15: TRUE | I15: TRUE | L15: בניה חדשה | M15: gush_helka | N15: בקשה להיתר | O15: היתר בתנאים | P15: 46329 | Q15: TRUE | R15: 45875 | S15: בקשה להיתר | T15: חמרא 40 אשקלון | U15: בניה חדשה רוויה | V15: בנייה רוויה דיור למשתכן | W15: 90 | Z15: אביסרור משה ובניו עבודות בנין ופתוח בע"מ | AA15: 362-93 | AB15: 13
A16: 20250266 | B16: status_advanced | C16: אשקלון | D16: מתחם_יג_מתחם_74494_מגרש_120_אשקלון | E16: עיוש רפאל בשכונת אבן עזרא אשקלון | F16: 1196-79 , 1196-81 , 1196-88 , 1196-89 , 1196-90 | G16: תמל/1048+120 | H16: TRUE | I16: TRUE | L16: בניה חדשה | M16: gush_helka | N16: היתר בתנאים | O16: היתר | P16: 46271 | Q16: TRUE | R16: 45875 | S16: בקשה להיתר | T16: טרם נקבעה כתובת למגרש אשקלון | U16: בניה חדשה רוויה | V16: בנייה רוויה דיור למשתכן | W16: 128 | Z16: עיוש רפאל בע"מ | AA16: 1196-90 | AB16: 120
A17: 20250351 | B17: untracked | H17: TRUE | I17: FALSE | J17: לא רלוונטי-בקשה של העיריה למבני ציבור | O17: היתר | P17: 14/05/2026 | Q17: TRUE | R17: 27/07/2025 | S17: בקשה להיתר | T17: הגתות 8 אשקלון | U17: בניה חדשה | V17: מבני ציבור | Z17: עיריית אשקלון | AA17: 388-1 | AB17: 936
A18: 20250352 | B18: untracked | H18: TRUE | I18: FALSE | J18: לא רלוונטי-בקשה של העיריה למבני ציבור | O18: היתר בתנאים | P18: 17/09/2025 | Q18: TRUE | R18: 27/07/2025 | S18: בקשה להיתר | T18: שאר ישוב 27 אשקלון | U18: בניה חדשה | V18: מבני ציבור | Z18: עיריית אשקלון | AA18: 1203-19 | AB18: 960A
A19: 20250353 | B19: untracked | H19: TRUE | I19: FALSE | J19: לא רלוונטי-בקשה של העיריה למבני ציבור | O19: היתר בתנאים | P19: 17/11/2025 | Q19: TRUE | R19: 27/07/2025 | S19: בקשה להיתר | T19: הכורמים 6 אשקלון | U19: בניה חדשה | V19: מבני ציבור | Z19: עיריית אשקלון | AA19: 1203-14 | AB19: 958
A20: 20250376 | B20: untracked | H20: TRUE | I20: FALSE | J20: לא רלוונטי-אכסניית נוער | Q20: TRUE | R20: 45785 | S20: בקשה להיתר | T20: הקונכייה 1 אשקלון | U20: בניה חדשה | V20: מלונאות (איכסון מלונאי) | W20: 93 | Z20: אגודת אכסניית נוער בישראל | AA20: 2950-41 | AB20: 23
A21: 20250397 | B21: untracked | H21: TRUE | I21: FALSE | J21: לא רלוונטי-צמוד קרקע של יזם פרטי | O21: היתר | P21: 46147 | Q21: TRUE | R21: 14/08/2025 | S21: בקשה להיתר | T21: יונה 7 אשקלון | U21: הריסה ובניה מחדש | V21: מגורים. | Z21: ואדעי ישי | AA21: 1207-144 | AB21: 273
A22: 20250401 | B22: untracked | H22: TRUE | I22: FALSE | J22: לא רלוונטי-בקשה של העיריה למבני ציבור | O22: היתר | P22: 26/02/2026 | Q22: TRUE | R22: 14/08/2025 | S22: בקשה להיתר | T22: רמב"ם 19 אשקלון | U22: בניה חדשה | V22: מבני ציבור | Z22: עיריית אשקלון | AA22: 1201-104 | AB22: 306
A23: 20250409 | B23: untracked | H23: TRUE | I23: FALSE | J23: לא רלוונטי-צמוד קרקע של יזם פרטי | O23: היתר | P23: 46113 | Q23: TRUE | R23: 20/08/2025 | S23: בקשה להיתר | T23: עמיעד 13 אשקלון | U23: הריסה ובניה מחדש | V23: מגורים. | Z23: דרנקובסקי מקסים | AA23: 3051-72 | AB23: 28
A24: 20250437 | B24: status_advanced | C24: אשקלון | D24: מתחם_78377_78375_אבן_עזרא_אשקלון | E24: מגרשים 102, 106 באבן עזרא אשקלון | F24: 1197-79 , 1197-84 , 1197-85 , 1197-86 , 1197-89 , 1197-90 , 1197-98 | G24: תמל/1048+102 , תמל/1048+106 | H24: TRUE | I24: TRUE | L24: בניה חדשה | M24: gush_helka | N24: בקשה להיתר | O24: היתר בתנאים | P24: 46329 | Q24: TRUE | R24: 45970 | S24: בקשה להיתר | T24: הרב יוסף שרביט 18 אשקלון | U24: בניה חדשה רוויה | V24: בנייה רוויה דיור למשתכן | Z24: שגיא אלמקייס יזמות ובניה בע"מ | AA24: 1197-85 | AB24: 106
A25: 20250506 | B25: untracked | H25: TRUE | I25: FALSE | J25: לא רלוונטי-בקשה של העיריה למבני ציבור | O25: היתר בתנאים | P25: 16/02/2026 | Q25: TRUE | R25: 23/10/2025 | S25: בקשה להיתר | T25: רפסודה 2 אשקלון | U25: בניה חדשה | V25: מבני ציבור | Z25: עיריית אשקלון | AA25: 2950-54 | AB25: 33
A26: 20250524 | B26: untracked | H26: TRUE | I26: FALSE | J26: לא רלוונטי-בקשה של העיריה למבני ציבור | Q26: TRUE | R26: 45699 | S26: בקשה להיתר | T26: חזון עובדיה 22 אשקלון | U26: בניה חדשה | V26: מבני ציבור | Z26: עיריית אשקלון | AA26: 1475-1 | AB26: 406
A27: 20250562 | B27: untracked | H27: TRUE | I27: FALSE | J27: לא רלוונטי-בקשה של העיריה למבני ציבור | O27: היתר בתנאים | P27: 46357 | Q27: TRUE | R27: 24/11/2025 | S27: בקשה להיתר | T27: רפסודה אשקלון | U27: בניה חדשה | V27: מבני ציבור | Z27: עיריית אשקלון | AA27: 2950-53 | AB27: 32
A28: 20250563 | B28: untracked | H28: TRUE | I28: FALSE | J28: לא רלוונטי-בקשה של העיריה למבני ציבור | O28: היתר בתנאים | P28: 46357 | Q28: TRUE | R28: 24/11/2025 | S28: בקשה להיתר | T28: הגלשן 11 אשקלון | U28: בניה חדשה | V28: מבני ציבור | Z28: עיריית אשקלון | AA28: 2950-20 | AB28: 36
A29: 20250609 | B29: untracked | H29: TRUE | I29: FALSE | J29: לא רלוונטי-צמוד קרקע של יזם פרטי | Q29: TRUE | R29: 16/12/2025 | S29: בקשה להיתר הקלות/ש.חורג | T29: חתן סופר 4 אשקלון | U29: הריסה ובניה מחדש | V29: מגורים. | Z29: מכלוף אלירן | AA29: 1962-99 | AB29: 99
A30: 20250610 | B30: untracked | H30: TRUE | I30: FALSE | J30: לא רלוונטי-צמוד קרקע של יזם פרטי | O30: היתר | P30: 28/05/2026 | Q30: TRUE | R30: 16/12/2025 | S30: בקשה להיתר | T30: בדולח 11 אשקלון | U30: הריסה ובניה מחדש | V30: מגורים. | Z30: אלון מרדכי | AA30: 1937-168 | AB30: 168
A31: 20250614 | B31: untracked | H31: TRUE | I31: FALSE | J31: לא רלוונטי-צמוד קרקע של יזם פרטי | O31: היתר בתנאים | P31: 46357 | Q31: TRUE | R31: 16/12/2025 | S31: בקשה להיתר | T31: רבי רפאל אנקווה 16 אשקלון | U31: בניה חדשה צמודי קרקע | V31: מגורים. | Z31: שחר רוני | AA31: 1938-207 | AB31: 218
A32: 20250622 | B32: untracked | H32: TRUE | I32: FALSE | J32: לא רלוונטי-צמוד קרקע של יזם פרטי | O32: היתר בתנאים | P32: 19/04/2026 | Q32: TRUE | R32: 21/12/2025 | S32: בקשה להיתר הקלות/ש.חורג | T32: האלון 6 אשקלון | U32: הריסה ובניה מחדש | V32: מגורים. | Z32: זיו משה (עבור גלאם תומר וטלי) | AA32: 1961-44
A33: 20250624 | B33: untracked | H33: TRUE | I33: FALSE | J33: לא רלוונטי-צמוד קרקע של יזם פרטי | O33: היתר בתנאים | P33: 46055 | Q33: TRUE | R33: 22/12/2025 | S33: בקשה להיתר | T33: סלעית 4 אשקלון | U33: הריסה ובניה מחדש | V33: מגורים. | Z33: סמיון ציטקילוב | AA33: 3046-79 | AB33: 30
A34: 20250640 | B34: untracked | H34: TRUE | I34: FALSE | J34: לא רלוונטי-צמוד קרקע של יזם פרטי | O34: היתר בתנאים | P34: 25/05/2026 | Q34: TRUE | R34: 30/12/2025 | S34: בקשה להיתר | T34: הרב אריה לוין 5 אשקלון | U34: בניה חדשה צמודי קרקע | V34: מגורים. | Z34: בוכריס אברהם | AA34: 1966-144 | AB34: 264
A35: 20260016 | B35: untracked | H35: TRUE | I35: FALSE | J35: הוקם דף פרויקט חדש | K35: דרום_אפריקה_1_אשקלון | O35: היתר בתנאים | P35: 16/06/2026 | Q35: TRUE | R35: 46235 | S35: בקשה להיתר | T35: שד' דרום אפריקה 1 אשקלון | U35: הריסה ובניה מחדש | V35: מגורים. | W35: 80 | Z35: אתגר ריינבו באשקלון 1 בע"מ | AA35: 1960-100
A36: 20260082 | B36: untracked | H36: TRUE | I36: FALSE | J36: לא רלוונטי-צמוד קרקע של יזם פרטי | O36: היתר בתנאים | P36: 46331 | Q36: TRUE | R36: 46297 | S36: בקשה להיתר | T36: דרכי נועם 3 אשקלון | U36: בניה חדשה צמודי קרקע | V36: מגורים חדש-צמודי קרקע | Z36: קסנטיני שון | AA36: 375-72 | AB36: 667
A37: 20260096 | B37: untracked | H37: TRUE | I37: FALSE | J37: הוקם דף פרויקט חדש | K37: מגרש_605_בעיר_היין_אשקלון_מסחרי | Q37: TRUE | R37: 22/02/2026 | S37: בקשה להיתר | T37: המייל השלישי 62 אשקלון | U37: בניה חדשה | V37: מסחר ותעסוקה | Z37: שגר עיר יין בע"מ | AA37: 368-62 | AB37: 605
A38: 20260135 | B38: untracked | H38: TRUE | I38: FALSE | J38: לא רלוונטי-צמוד קרקע של יזם פרטי | O38: היתר בתנאים | P38: 27/04/2026 | Q38: TRUE | R38: 25/03/2026 | S38: בקשה להיתר | T38: אופירה 10 אשקלון | U38: הריסה ובניה מחדש | V38: מגורים. | Z38: אלימלך אלמוג | AA38: 3051-77 | AB38: 42
A39: 20260180 | B39: untracked | H39: TRUE | I39: FALSE | J39: לא רלוונטי-צמוד קרקע של יזם פרטי | O39: היתר | P39: 21/06/2026 | Q39: TRUE | R39: 26/04/2026 | S39: בקשה להיתר | T39: עשרת השבטים 23 אשקלון | U39: הריסה ובניה מחדש | V39: מגורים. | Z39: אלחזוב זלמן | AA39: 3050-36 | AB39: 29
A40: 20260223 | B40: untracked | H40: TRUE | I40: FALSE | J40: לא רלוונטי-צמוד קרקע של יזם פרטי | O40: היתר בתנאים | P40: 46240 | Q40: TRUE | R40: 18/05/2026 | S40: בקשה להיתר | T40: מקור הברכה 30 אשקלון | U40: בניה חדשה צמודי קרקע | V40: מגורים חדש-צמודי קרקע | Z40: לוי אלי | AA40: 375-62 | AB40: 611
...

Sheet רשימת בקשות מעודכנת
A1: request_number | B1: vlookup | C1: flag | D1: city | E1: project_id | F1: project_name | G1: project_sug_bnia | H1: project_gush_helka | I1: project_migrash | J1: match_method | K1: db_status | L1: scraped_status | M1: scraped_status_date | N1: type_confirmed | O1: request_date | P1: request_category | Q1: full_address | R1: request_type | S1: shimush_ikari | T1: unit_count | U1: manual_review_event | V1: bakasha_description | W1: requestor | X1: permit_block_lot | Y1: permit_migrash | Z1: request_url
A2: 20160086 | B2: =VLOOKUP(A2,'רשימת בקשות לעבור עליהם'!$A:$A,1,0) -> 20160086 | C2: status_advanced | D2: אשקלון | E2: גרופית_באגמים | F2: טופ אגמים - אשקלון | G2: בניה חדשה | H2: 2886-8 , 2886-9 , 2886-10 | I2: 120/101/02/4+307 , 120/101/02/4+402 , 120/101/02/4+403 | J2: gush_helka | K2: היתר בניה | L2: טופס 4 | M2: 27/10/2022 | N2: TRUE | O2: 42402 | P2: בקשה להיתר | Q2: מפל התנור 10 אשקלון | R2: בניה חדשה רוויה | S2: מגורים חדש -רוויה | T2: 116 | W2: גרופית נכסים והנדסה(1993)בע"מ | X2: 360405 | Y2: 403 | Z2: https://ashkelon.complot.co.il/newengine/Pages/request2.aspx#request/20160086
A3: 20160462 | B3: =VLOOKUP(A3,'רשימת בקשות לעבור עליהם'!$A:$A,1,0) -> 20160462 | C3: status_advanced | D3: אשקלון | E3: אגמים_אשקלון | F3: אגמים אשקלון | G3: בניה חדשה | H3: 358852 | I3: 120/101/02/4+200 | J3: gush_helka | K3: היתר בניה | L3: טופס 4 | M3: 43474 | N3: TRUE | O3: 15/03/2016 | P3: בקשה להיתר | Q3: שד' עמק יזרעאל 3 אשקלון | R3: בניה חדשה רוויה | S3: מגורים חדש -רוויה | T3: 33 | W3: רונידן חב' לבנין בע"מ | X3: 358852 | Y3: 200 | Z3: https://ashkelon.complot.co.il/newengine/Pages/request2.aspx#request/20160462
A4: 20160463 | B4: =VLOOKUP(A4,'רשימת בקשות לעבור עליהם'!$A:$A,1,0) -> 20160463 | C4: status_advanced | D4: אשקלון | E4: אגמים_אשקלון | F4: אגמים אשקלון | G4: בניה חדשה | H4: 358852 | I4: 120/101/02/4+200 | J4: gush_helka | K4: היתר בניה | L4: טופס 4 | M4: 31/07/2022 | N4: TRUE | O4: 15/03/2016 | P4: בקשה להיתר | Q4: נחל פרת 3 אשקלון | R4: בניה חדשה רוויה | S4: מגורים חדש -רוויה | T4: 27 | W4: אבי נמני הנדסה ובנין בע"מ | X4: 358852 | Y4: 200 | Z4: https://ashkelon.complot.co.il/newengine/Pages/request2.aspx#request/20160463
A5: 20190022 | B5: =VLOOKUP(A5,'רשימת בקשות לעבור עליהם'!$A:$A,1,0) -> 20190022 | C5: status_advanced | D5: אשקלון | E5: ליאם_נחמיאס_אשקלון__מתחם_1 | F5: ליאם נחמיאס בבלוט מתחם א אשקלון | G5: בניה חדשה | H5: 1967-15 , 1967-47 , 2950-10 | I5: 192/03/4+1 | J5: gush_helka | K5: היתר בניה | L5: טופס 4 | M5: 29/10/2023 | N5: TRUE | O5: 13/01/2019 | P5: בקשה להיתר הקלות/ש.חורג | Q5: שד' אריה תגר 15 אשקלון | R5: בניה חדשה רוויה | S5: בנייה רוויה דיור למשתכן | T5: 73 | W5: ליאם נחמיאס חב' לבנין בע"מ | X5: 383780 | Y5: 1 | Z5: https://ashkelon.complot.co.il/newengine/Pages/request2.aspx#request/20190022
A6: 20220191 | B6: =VLOOKUP(A6,'רשימת בקשות לעבור עליהם'!$A:$A,1,0) -> 20220191 | C6: status_advanced | D6: אשקלון | E6: אריה_עוזר_6-8_אשקלון | F6: אריה עוזר 6-8 אשקלון | G6: בניה חדשה | H6: 1241-58 , 1241-63 , 1241-90 | J6: gush_helka | K6: היתר בניה | L6: טופס 4 | M6: 30/09/2024 | N6: TRUE | O6: 15/03/2022 | P6: בקשה להיתר הקלות/ש.חורג | Q6: אריה עוזר 8 אשקלון | R6: בניה רוייה מעל 10 קומות | S6: מגורים חדש -רוויה | T6: 36 | W6: אורות גת בע"מ | X6: 1241-63 | Y6: 100 | Z6: https://ashkelon.complot.co.il/newengine/Pages/request2.aspx#request/20220191
A7: 20200694 | B7: =VLOOKUP(A7,'רשימת בקשות לעבור עליהם'!$A:$A,1,0) -> 20200694 | C7: status_advanced | D7: אשקלון | E7: משה_דיין_9_אשקלון | F7: YAMA דמרי במרינה אשקלון | G7: בניה חדשה | H7: 1938-433 , 1938-441 | J7: gush_helka | K7: היתר בניה | L7: טופס 4 | M7: 46174 | N7: TRUE | O7: 19/10/2020 | P7: בקשה להיתר הקלות/ש.חורג | Q7: משה דיין 9 אשקלון | R7: בניה רוייה מעל 10 קומות | S7: מגורים חדש -רוויה | T7: 327 | W7: י.ח. דמרי בניה ופיתוח | X7: 1938-433 | Y7: 1 | Z7: https://ashkelon.complot.co.il/newengine/Pages/request2.aspx#request/20200694
A8: 20200787 | B8: =VLOOKUP(A8,'רשימת בקשות לעבור עליהם'!$A:$A,1,0) -> 20200787 | C8: status_advanced | D8: אשקלון | E8: כ_כוכב_הנגב_בבלוט_ח | F8: כ.כוכב הנגב בבלוט מתחם ב' | G8: בניה חדשה | H8: 1967-16 , 1967-17 , 2950-48 | I8: 192/03/4+14 | J8: gush_helka | K8: היתר בניה | L8: טופס 4 | M8: 18/03/2026 | N8: TRUE | O8: 29/10/2018 | P8: בקשה להיתר | Q8: זהבון 3 אשקלון | R8: בניה חדשה רוויה | S8: בנייה רוויה דיור למשתכן | T8: 133 | W8: כ.כוכב הנגב חב' לבנין ופתוח (1990) בע"מ | X8: 2950-48 | Y8: 14 | Z8: https://ashkelon.complot.co.il/newengine/Pages/request2.aspx#request/20200787
A9: 20210261 | B9: =VLOOKUP(A9,'רשימת בקשות לעבור עליהם'!$A:$A,1,0) -> 20210261 | C9: status_advanced | D9: אשקלון | E9: אשקלון_שכ'_צפונית_מתחם_30 | F9: ג.ג.א.ב יזום נכסים והשקעות בשכ' צפונית אשקלון מתחם ב' | G9: בניה חדשה | H9: 371-52 , 371-53 , 371-56 , 371-57 , 371-58 , 371-59 , 371-60 , 371-69 | I9: תמל/1006+114 , תמל/1006+311 | J9: gush_helka | K9: היתר בניה | L9: טופס 4 | M9: 30/04/2026 | N9: TRUE | O9: 13/04/2021 | P9: בקשה להיתר הקלות/ש.חורג | Q9: דרך ארץ 24 אשקלון | R9: בניה רוייה מעל 10 קומות | S9: בנייה רוויה דיור למשתכן | T9: 120 | W9: ג.ג.א.ב. ייזום נכסים והשקעות בע"מ | X9: 371-52 | Y9: 311 | Z9: https://ashkelon.complot.co.il/newengine/Pages/request2.aspx#request/20210261
A10: 20210262 | B10: =VLOOKUP(A10,'רשימת בקשות לעבור עליהם'!$A:$A,1,0) -> 20210262 | C10: status_advanced | D10: אשקלון | E10: אשקלון_שכ'_צפונית_מתחם_30 | F10: ג.ג.א.ב יזום נכסים והשקעות בשכ' צפונית אשקלון מתחם ב' | G10: בניה חדשה | H10: 371-52 , 371-53 , 371-56 , 371-57 , 371-58 , 371-59 , 371-60 , 371-69 | I10: תמל/1006+114 , תמל/1006+311 | J10: gush_helka | K10: היתר בניה | L10: טופס 4 | M10: 46149 | N10: TRUE | O10: 13/04/2021 | P10: בקשה להיתר הקלות/ש.חורג | Q10: דרך ארץ 18 אשקלון | R10: בניה רוייה מעל 10 קומות | S10: בנייה רוויה דיור למשתכן | T10: 206 | W10: ג.ג.א.ב. ייזום נכסים והשקעות בע"מ | X10: 371-56 | Y10: 114 | Z10: https://ashkelon.complot.co.il/newengine/Pages/request2.aspx#request/20210262
A11: 20210732 | B11: =VLOOKUP(A11,'רשימת בקשות לעבור עליהם'!$A:$A,1,0) -> 20210732 | C11: status_advanced | D11: אשקלון | E11: אשקלון_מתחם_44_מגרש_305 | F11: ליאם נחמיאס בעיר היין, מתחם 44, אשקלון | G11: בניה חדשה | H11: 369-52 , 369-63 , 369-71 , 369-72 , 369-76 | I11: תמל/1006+305 | J11: gush_helka | K11: היתר בניה | L11: טופס 4 | M11: 21/06/2026 | N11: TRUE | O11: 19/10/2021 | P11: בקשה להיתר הקלות/ש.חורג | Q11: דרך ארץ 34 אשקלון | R11: בניה חדשה רוויה | S11: בנייה רוויה דיור למשתכן | T11: 180 | W11: ליאם נחמיאס חב' לבנין בע"מ | X11: 369-71 | Y11: 305 | Z11: https://ashkelon.complot.co.il/newengine/Pages/request2.aspx#request/20210732
A12: 20210746 | B12: =VLOOKUP(A12,'רשימת בקשות לעבור עליהם'!$A:$A,1,0) -> 20210746 | C12: status_advanced | D12: אשקלון | E12: מגרש_203_214_אגמים_מזרח_אשקלון | F12: אביסרור באגמים הירוקה, אשקלון | G12: בניה חדשה | H12: 1474-61 , 1474-68 , 1474-71 , 1475-58 , 1476-67 | I12: תמל/1022+203 , תמל/1022+214 | J12: gush_helka | K12: היתר בניה | L12: טופס 4 | M12: 17/02/2025 | N12: TRUE | O12: 26/10/2021 | P12: בקשה להיתר הקלות/ש.חורג | Q12: נופר 1 אשקלון | R12: בניה חדשה רוויה | S12: בנייה רוויה דיור למשתכן | T12: 24 | W12: אביסרור משה ובניו עבודות בנין ופתוח בע"מ | X12: 1475-58 | Y12: 203 | Z12: https://ashkelon.complot.co.il/newengine/Pages/request2.aspx#request/20210746
A13: 20210795 | B13: =VLOOKUP(A13,'רשימת בקשות לעבור עליהם'!$A:$A,1,0) -> 20210795 | C13: status_advanced | D13: אשקלון | E13: מגרש_203_214_אגמים_מזרח_אשקלון | F13: אביסרור באגמים הירוקה, אשקלון | G13: בניה חדשה | H13: 1474-61 , 1474-68 , 1474-71 , 1475-58 , 1476-67 | I13: תמל/1022+203 , תמל/1022+214 | J13: gush_helka | K13: היתר בניה | L13: טופס 4 | M13: 46144 | N13: TRUE | O13: 14/11/2021 | P13: בקשה להיתר הקלות/ש.חורג | Q13: שד' עמק יזרעאל 75 אשקלון | R13: בניה רוייה מעל 10 קומות | S13: בנייה רוויה דיור למשתכן | T13: 78 | W13: אביסרור משה ובניו עבודות בנין ופתוח בע"מ | X13: 1476-67 | Y13: 214 | Z13: https://ashkelon.complot.co.il/newengine/Pages/request2.aspx#request/20210795
A14: 20220304 | B14: =VLOOKUP(A14,'רשימת בקשות לעבור עליהם'!$A:$A,1,0) -> 20220304 | C14: status_advanced | D14: אשקלון | E14: מתחם_71403_עיר_היין_אשקלון | F14: קבוצת נמיר נדל"ן במגרש 3 עיר היין אשקלון | G14: בניה חדשה | H14: 362-88 , 363-60 | I14: תמל/1006+3 | J14: gush_helka | K14: היתר בניה | L14: טופס 4 | M14: 45813 | N14: TRUE | O14: 28/04/2022 | P14: בקשה להיתר הקלות/ש.חורג | Q14: היינן 33 אשקלון | R14: בניה חדשה רוויה | S14: בנייה רוויה דיור למשתכן | T14: 90 | W14: נמיר בעיר היין בע"מ | X14: 362-88 | Y14: 3 | Z14: https://ashkelon.complot.co.il/newengine/Pages/request2.aspx#request/20220304
A15: 20220379 | B15: =VLOOKUP(A15,'רשימת בקשות לעבור עליהם'!$A:$A,1,0) -> 20220379 | C15: status_advanced | D15: אשקלון | E15: מתחם_54242_אשקלון | F15: שדרות בגין מנחם 28, אשקלון | G15: בניה חדשה | H15: 357606 | I15: 108/101/02/4+145 | J15: gush_helka | K15: היתר בניה | L15: טופס 4 | M15: 18/06/2026 | N15: TRUE | O15: 44567 | P15: בקשה להיתר הקלות/ש.חורג | Q15: בגין מנחם 28 אשקלון | R15: מבנה מגורים+מסחר מעל 10 ק | S15: מגורים חדש -רוויה | T15: 109 | W15: רם אדרת מגורים בע"מ | X15: 357606 | Y15: 145 | Z15: https://ashkelon.complot.co.il/newengine/Pages/request2.aspx#request/20220379
A16: 20220876 | B16: =VLOOKUP(A16,'רשימת בקשות לעבור עליהם'!$A:$A,1,0) -> 20220876 | C16: status_advanced | D16: אשקלון | E16: אריה_עוזר_6-8_אשקלון | F16: אריה עוזר 6-8 אשקלון | G16: בניה חדשה | H16: 1241-58 , 1241-63 , 1241-90 | J16: gush_helka | K16: היתר בניה | L16: טופס 4 | M16: 30/09/2024 | N16: TRUE | O16: 44754 | P16: בקשה להיתר הקלות/ש.חורג | Q16: אריה עוזר 6 אשקלון | R16: בניה רוייה מעל 10 קומות | S16: מגורים חדש -רוויה | T16: 36 | W16: אורות גת בע"מ | X16: 1241-63 | Y16: 100 | Z16: https://ashkelon.complot.co.il/newengine/Pages/request2.aspx#request/20220876
A17: 20220878 | B17: =VLOOKUP(A17,'רשימת בקשות לעבור עליהם'!$A:$A,1,0) -> 20220878 | C17: status_advanced | D17: אשקלון | E17: אריה_עוזר_6-8_אשקלון | F17: אריה עוזר 6-8 אשקלון | G17: בניה חדשה | H17: 1241-58 , 1241-63 , 1241-90 | J17: gush_helka | K17: היתר בניה | L17: טופס 4 | M17: 28/01/2026 | N17: TRUE | O17: 44754 | P17: בקשה להיתר הקלות/ש.חורג | Q17: צפניה 25 אשקלון | R17: בניה רוייה מעל 10 קומות | S17: מגורים חדש -רוויה | T17: 72 | W17: אורות גת בע"מ | X17: 1241-63 | Y17: 100 | Z17: https://ashkelon.complot.co.il/newengine/Pages/request2.aspx#request/20220878
A18: 20220897 | B18: =VLOOKUP(A18,'רשימת בקשות לעבור עליהם'!$A:$A,1,0) -> 20220897 | C18: status_advanced | D18: אשקלון | E18: החלוץ_פינת_דוד_רמז_אשקלון | F18: החלוץ פינת דוד רמז, אשקלון | G18: בניה חדשה | H18: 1247-35 , 1247-38 , 1297-1 , 1297-3 | J18: gush_helka | K18: היתר בניה | L18: טופס 4 | M18: 13/04/2026 | N18: TRUE | O18: 13/12/2022 | P18: בקשה להיתר הקלות/ש.חורג | Q18: החלוץ אשקלון | R18: מבנה מגורים משולב במסחר | S18: דיור מיוחד,מסחר,משרדים | T18: 22 | W18: ד.י. דוידי השק' בנדל"ן בע"מ | X18: 1297-3 | Z18: https://ashkelon.complot.co.il/newengine/Pages/request2.aspx#request/20220897
A19: 20230224 | B19: =VLOOKUP(A19,'רשימת בקשות לעבור עליהם'!$A:$A,1,0) -> 20230224 | C19: status_advanced | D19: אשקלון | E19: משה_דיין_9_אשקלון | F19: YAMA דמרי במרינה אשקלון | G19: בניה חדשה | H19: 1938-433 , 1938-441 | J19: gush_helka | K19: היתר בניה | L19: טופס 4 | M19: 13/08/2025 | N19: TRUE | O19: 45049 | P19: בקשה להיתר | Q19: משה דיין 9 אשקלון | R19: בניה רוייה מעל 10 קומות | S19: מגורים. | W19: י.ח. דמרי בניה ופיתוח בע"מ | X19: 1938-433 | Y19: 1 | Z19: https://ashkelon.complot.co.il/newengine/Pages/request2.aspx#request/20230224
A20: 20230313 | B20: =VLOOKUP(A20,'רשימת בקשות לעבור עליהם'!$A:$A,1,0) -> 20230313 | C20: status_advanced | D20: אשקלון | E20: הרב_בוזגלו_דוד_69_אשקלון | F20: הרב בוזגלו דוד 69 אשקלון | G20: בניה חדשה | H20: 1966-396 | J20: gush_helka | K20: היתר בתנאים | L20: היתר | M20: 25/03/2026 | N20: TRUE | O20: 16/05/2024 | P20: בקשה להיתר הקלות/ש.חורג | Q20: הרב דוד בוזגלו 71 אשקלון | R20: בניה חדשה רוויה | S20: מגורים חדש -רוויה | T20: 16 | W20: ש.מ. חופית הנדסה ובניה בע"מ | X20: 1966-396 | Y20: 396 | Z20: https://ashkelon.complot.co.il/newengine/Pages/request2.aspx#request/20230313
A21: 20230593 | B21: =VLOOKUP(A21,'רשימת בקשות לעבור עליהם'!$A:$A,1,0) -> 20230593 | C21: status_advanced | D21: אשקלון | E21: הרב_בוזגלו_דוד_26_אשקלון | F21: הרב בוזגלו דוד 26 אשקלון | G21: בניה חדשה | H21: 1936-348 | J21: gush_helka | K21: היתר בתנאים | L21: היתר | M21: 25/02/2026 | N21: TRUE | O21: 45993 | P21: בקשה להיתר הקלות/ש.חורג | Q21: הרב דוד בוזגלו 26 אשקלון | R21: בניה חדשה | S21: מסחר/משרדים | W21: וואסט מ.ל נכסים 2006 בע"מ | X21: 1936-348 | Y21: 1102 | Z21: https://ashkelon.complot.co.il/newengine/Pages/request2.aspx#request/20230593
A22: 20230759 | B22: =VLOOKUP(A22,'רשימת בקשות לעבור עליהם'!$A:$A,1,0) -> 20230759 | C22: status_advanced | D22: אשקלון | E22: מגרש_110_אבן_עזרא_אשקלון | F22: אבני חושן | G22: בניה חדשה | H22: 1197-87 , 1197-89 , 1197-90 , 1197-91 , 1197-92 , 1197-93 , 1197-95 , 1197-100 | I22: תמל/1048+108 , תמל/1048+110 | J22: gush_helka | K22: היתר בניה | L22: טופס 4 | M22: 23/06/2026 | N22: TRUE | O22: 45211 | P22: בקשה להיתר הקלות/ש.חורג | Q22: הרב יוסף שרביט 5 אשקלון | R22: בניה חדשה רוויה | S22: בנייה רוויה דיור למשתכן | T22: 102 | W22: א.ד.מ. בוני ישראל יזמות ובניה בע"מ | X22: 1197-87 | Y22: 108 | Z22: https://ashkelon.complot.co.il/newengine/Pages/request2.aspx#request/20230759
A23: 20240290 | B23: =VLOOKUP(A23,'רשימת בקשות לעבור עליהם'!$A:$A,1,0) -> 20240290 | C23: status_advanced | D23: אשקלון | E23: מגרש_138_בעיר_היין_אשקלון | F23: מגרש 138 בעיר היין אשקלון | G23: בניה חדשה | H23: 1199-60 , 1199-67 , 1199-79 , 1199-81 | I23: תמל/1006+138 | J23: gush_helka | K23: היתר בתנאים | L23: היתר | M23: 16/03/2026 | N23: TRUE | O23: 45690 | P23: בקשה להיתר הקלות/ש.חורג | Q23: היוצרים 45 אשקלון | R23: בניה רוייה מעל 10 קומות | S23: בנייה רוויה דיור למשתכן | T23: 116 | W23: גוהרי יוסי השקעות בע"מ | X23: 1199-67 | Y23: 138 | Z23: https://ashkelon.complot.co.il/newengine/Pages/request2.aspx#request/20240290
A24: 20240348 | B24: =VLOOKUP(A24,'רשימת בקשות לעבור עליהם'!$A:$A,1,0) -> 20240348 | C24: status_advanced | D24: אשקלון | E24: מתחם_ג_מתחם_74484_מגרש_107_אשקלון | F24: מ.א.י אביבי ייזום ובנייה בשכונת אבן עזרא אשקלון | G24: בניה חדשה | H24: 1197-93 , 1197-94 , 1197-95 , 1197-96 | I24: תמל/1048+107 | J24: gush_helka | K24: היתר בתנאים | L24: היתר | M24: 22/06/2026 | N24: TRUE | O24: 24/06/2024 | P24: בקשה להיתר הקלות/ש.חורג | Q24: הרב יוסף שרביט 3 אשקלון | R24: בניה רוייה מעל 10 קומות | S24: בנייה רוויה דיור למשתכן | T24: 97 | W24: מ.א.י אביבי ייזום ובניה בע"מ | X24: 1197-93 | Y24: 107 | Z24: https://ashkelon.complot.co.il/newengine/Pages/request2.aspx#request/20240348
A25: 20240650 | B25: =VLOOKUP(A25,'רשימת בקשות לעבור עליהם'!$A:$A,1,0) -> 20240650 | C25: status_advanced | D25: אשקלון | E25: מתחם_ב_מתחם_74483_מגרש_105_אשקלון | F25: האחים בוסקילה מגרש 105 בשכונת אבן עזרא אשקלון | G25: בניה חדשה | H25: 1197-81 , 1197-82 , 1197-83 , 1197-85 , 1197-86 , 1197-87 , 1197-98 | I25: תמל/1048+105 | J25: gush_helka | K25: היתר בתנאים | L25: היתר | M25: 26/03/2026 | N25: TRUE | O25: 45394 | P25: בקשה להיתר הקלות/ש.חורג | Q25: טרם נקבעה כתובת למגרש אשקלון | R25: מבנה מגורים+מסחר מעל 10 ק | S25: בנייה רוויה דיור למשתכן | T25: 112 | W25: חברת אחים בוסקילה בע"מ | X25: 1197-81 | Y25: 105 | Z25: https://ashkelon.complot.co.il/newengine/Pages/request2.aspx#request/20240650
A26: 20240697 | B26: =VLOOKUP(A26,'רשימת בקשות לעבור עליהם'!$A:$A,1,0) -> 20240697 | C26: status_advanced | D26: אשקלון | E26: מגרש_200_201_אבן_עזרא_אשקלון | F26: גשם החזקות באבן עזרא אשקלון | G26: בניה חדשה | H26: 1197-77 , 1197-78 , 1197-82 , 1197-97 , 1198-50 , 1198-52 , 1198-72 | I26: תמל/1048+200 , תמל/1048+201 | J26: gush_helka | K26: טרום בקשה | L26: היתר בתנאים | M26: 17/03/2026 | N26: TRUE | O26: 18/12/2024 | P26: בקשה להיתר הקלות/ש.חורג | Q26: טרם נקבעה כתובת למגרש אשקלון | R26: בניה חדשה רוויה | S26: בנייה רוויה דיור למשתכן | T26: 130 | W26: יורו גשם בע"מ | X26: 1197-82 | Y26: 201 | Z26: https://ashkelon.complot.co.il/newengine/Pages/request2.aspx#request/20240697
A27: 20240698 | B27: =VLOOKUP(A27,'רשימת בקשות לעבור עליהם'!$A:$A,1,0) -> 20240698 | C27: status_advanced | D27: אשקלון | E27: מגרש_200_201_אבן_עזרא_אשקלון | F27: גשם החזקות באבן עזרא אשקלון | G27: בניה חדשה | H27: 1197-77 , 1197-78 , 1197-82 , 1197-97 , 1198-50 , 1198-52 , 1198-72 | I27: תמל/1048+200 , תמל/1048+201 | J27: gush_helka | K27: טרום בקשה | L27: היתר בתנאים | M27: 17/03/2026 | N27: TRUE | O27: 18/12/2024 | P27: בקשה להיתר הקלות/ש.חורג | Q27: טרם נקבעה כתובת למגרש אשקלון | R27: בניה חדשה רוויה | S27: בנייה רוויה דיור למשתכן | W27: יורו גשם בע"מ | X27: 1197-77 | Y27: 200 | Z27: https://ashkelon.complot.co.il/newengine/Pages/request2.aspx#request/20240698
A28: 20250098 | B28: =VLOOKUP(A28,'רשימת בקשות לעבור עליהם'!$A:$A,1,0) -> 20250098 | C28: status_advanced | D28: אשקלון | E28: הכורמים_60_אשקלון | F28: צפריר וזוהר שרבט בעיר היין אשקלון | G28: בניה חדשה | H28: 1199-65 , 1199-66 , 1199-79 | I28: תמל/1006+117 | J28: gush_helka | K28: היתר בתנאים | L28: היתר | M28: 24/03/2026 | N28: TRUE | O28: 22/02/2025 | P28: בקשה להיתר | Q28: דרך ארץ 13 אשקלון | R28: בניה רוייה מעל 10 קומות | S28: בנייה רוויה דיור למשתכן | T28: 104 | W28: זוהר וצפריר שרבט בע"מ | X28: 1199-65 | Y28: 117 | Z28: https://ashkelon.complot.co.il/newengine/Pages/request2.aspx#request/20250098
A29: 20250129 | B29: =VLOOKUP(A29,'רשימת בקשות לעבור עליהם'!$A:$A,1,0) -> 20250129 | C29: status_advanced | D29: אשקלון | E29: מתחם_א_מתחם_74482_מגרש_100_אשקלון | F29: י.ח דמרי בניה ופיתוח בשכונת אבן עזרא אשקלון | G29: בניה חדשה | H29: 1197-78 , 1197-80 , 1197-81 , 1197-82 , 1197-97 | I29: תמל/1048+100 | J29: gush_helka | K29: היתר בתנאים | L29: היתר | M29: 25/01/2026 | N29: TRUE | O29: 45933 | P29: בקשה להיתר הקלות/ש.חורג | Q29: טרם נקבעה כתובת למגרש אשקלון | R29: בניה רוייה מעל 10 קומות | S29: בנייה רוויה דיור למשתכן | T29: 104 | W29: י.ח.דמרי בניה ופיתוח בע"מ. | X29: 1197-78 | Y29: 100 | Z29: https://ashkelon.complot.co.il/newengine/Pages/request2.aspx#request/20250129
A30: 20250232 | B30: =VLOOKUP(A30,'רשימת בקשות לעבור עליהם'!$A:$A,1,0) -> 20250232 | C30: status_advanced | D30: אשקלון | E30: מגרש_106_עיר_היין_אשקלון | F30: מגרש 106 בעיר היין אשקלון | G30: בניה חדשה | H30: 363-63 , 363-65 , 363-71 , 363-73 , 363-75 | I30: תמל/1006+106 | J30: gush_helka | K30: היתר בתנאים | L30: היתר | M30: 29/06/2026 | N30: TRUE | O30: 19/05/2025 | P30: בקשה להיתר | Q30: דרך ארץ 56 אשקלון | R30: בניה רוייה מעל 10 קומות | S30: מגורים - רישוי זמין | T30: 180 | W30: אביסרור משה ובניו עבודות בנין ופתוח בע"מ | X30: 363-75 | Y30: 106 | Z30: https://ashkelon.complot.co.il/newengine/Pages/request2.aspx#request/20250232
A31: 20250262 | B31: =VLOOKUP(A31,'רשימת בקשות לעבור עליהם'!$A:$A,1,0) -> 20250262 | C31: status_advanced | D31: אשקלון | E31: מגרש_13_בעיר_היין_אשקלון | F31: מגרש 13 בעיר היין אשקלון | G31: בניה חדשה | H31: 362-93 , 362-94 , 362-95 , 362-98 , 369-58 , 369-59 | I31: תמל/1006+13 | J31: gush_helka | K31: בקשה להיתר | L31: היתר בתנאים | M31: 46329 | N31: TRUE | O31: 45875 | P31: בקשה להיתר | Q31: חמרא 40 אשקלון | R31: בניה חדשה רוויה | S31: בנייה רוויה דיור למשתכן | T31: 90 | W31: אביסרור משה ובניו עבודות בנין ופתוח בע"מ | X31: 362-93 | Y31: 13 | Z31: https://ashkelon.complot.co.il/newengine/Pages/request2.aspx#request/20250262
A32: 20250266 | B32: =VLOOKUP(A32,'רשימת בקשות לעבור עליהם'!$A:$A,1,0) -> 20250266 | C32: status_advanced | D32: אשקלון | E32: מתחם_יג_מתחם_74494_מגרש_120_אשקלון | F32: עיוש רפאל בשכונת אבן עזרא אשקלון | G32: בניה חדשה | H32: 1196-79 , 1196-81 , 1196-88 , 1196-89 , 1196-90 | I32: תמל/1048+120 | J32: gush_helka | K32: היתר בתנאים | L32: היתר | M32: 46271 | N32: TRUE | O32: 45875 | P32: בקשה להיתר | Q32: טרם נקבעה כתובת למגרש אשקלון | R32: בניה חדשה רוויה | S32: בנייה רוויה דיור למשתכן | T32: 128 | W32: עיוש רפאל בע"מ | X32: 1196-90 | Y32: 120 | Z32: https://ashkelon.complot.co.il/newengine/Pages/request2.aspx#request/20250266
A33: 20250354 | B33: =VLOOKUP(A33,'רשימת בקשות לעבור עליהם'!$A:$A,1,0) -> 20250354 | C33: status_advanced | D33: אשקלון | E33: דוריף_85_אשקלון | F33: רמט טרום במתחם 74532-74533 עיר היין אשקלון | G33: בניה חדשה | H33: 362-101 , 362-103 , 362-105 , 363-73 , 363-75 | I33: תמל/1006+104 , תמל/1006+105 | J33: gush_helka | K33: בקשה להיתר | L33: היתר בתנאים | M33: 46329 | N33: TRUE | O33: 27/07/2025 | P33: בקשה להיתר הקלות/ש.חורג | Q33: אריאל שרון 56 אשקלון | R33: בניה רוייה מעל 10 קומות | S33: בנייה רוויה דיור למשתכן | T33: 108 | W33: רמט טרום בע"מ | X33: 362-101 | Y33: 104 | Z33: https://ashkelon.complot.co.il/newengine/Pages/request2.aspx#request/20250354
A34: 20250355 | B34: =VLOOKUP(A34,'רשימת בקשות לעבור עליהם'!$A:$A,1,0) -> 20250355 | C34: status_advanced | D34: אשקלון | E34: דוריף_85_אשקלון | F34: רמט טרום במתחם 74532-74533 עיר היין אשקלון | G34: בניה חדשה | H34: 362-101 , 362-103 , 362-105 , 363-73 , 363-75 | I34: תמל/1006+104 , תמל/1006+105 | J34: gush_helka | K34: בקשה להיתר | L34: היתר בתנאים | M34: 46329 | N34: TRUE | O34: 27/07/2025 | P34: בקשה להיתר הקלות/ש.חורג | Q34: אריאל שרון 62 אשקלון | R34: בניה רוייה מעל 10 קומות | S34: בנייה רוויה דיור למשתכן | T34: 108 | W34: רמט טרום בע"מ | X34: 362-105 | Y34: 105 | Z34: https://ashkelon.complot.co.il/newengine/Pages/request2.aspx#request/20250355
A35: 20250376 | B35: =VLOOKUP(A35,'רשימת בקשות לעבור עליהם'!$A:$A,1,0) -> 20250376 | C35: untracked | N35: TRUE | O35: 45785 | P35: בקשה להיתר | Q35: הקונכייה 1 אשקלון | R35: בניה חדשה | S35: מלונאות (איכסון מלונאי) | T35: 93 | W35: אגודת אכסניית נוער בישראל | X35: 2950-41 | Y35: 23 | Z35: https://ashkelon.complot.co.il/newengine/Pages/request2.aspx#request/20250376
A36: 20250397 | B36: =VLOOKUP(A36,'רשימת בקשות לעבור עליהם'!$A:$A,1,0) -> 20250397 | C36: untracked | L36: היתר | M36: 46147 | N36: TRUE | O36: 14/08/2025 | P36: בקשה להיתר | Q36: יונה 7 אשקלון | R36: הריסה ובניה מחדש | S36: מגורים. | W36: ואדעי ישי | X36: 1207-144 | Y36: 273 | Z36: https://ashkelon.complot.co.il/newengine/Pages/request2.aspx#request/20250397
A37: 20250409 | B37: =VLOOKUP(A37,'רשימת בקשות לעבור עליהם'!$A:$A,1,0) -> 20250409 | C37: untracked | L37: היתר | M37: 46113 | N37: TRUE | O37: 20/08/2025 | P37: בקשה להיתר | Q37: עמיעד 13 אשקלון | R37: הריסה ובניה מחדש | S37: מגורים. | W37: דרנקובסקי מקסים | X37: 3051-72 | Y37: 28 | Z37: https://ashkelon.complot.co.il/newengine/Pages/request2.aspx#request/20250409
A38: 20250437 | B38: =VLOOKUP(A38,'רשימת בקשות לעבור עליהם'!$A:$A,1,0) -> 20250437 | C38: status_advanced | D38: אשקלון | E38: מתחם_78377_78375_אבן_עזרא_אשקלון | F38: מגרשים 102, 106 באבן עזרא אשקלון | G38: בניה חדשה | H38: 1197-79 , 1197-84 , 1197-85 , 1197-86 , 1197-89 , 1197-90 , 1197-98 | I38: תמל/1048+102 , תמל/1048+106 | J38: gush_helka | K38: בקשה להיתר | L38: היתר בתנאים | M38: 46329 | N38: TRUE | O38: 45970 | P38: בקשה להיתר | Q38: הרב יוסף שרביט 18 אשקלון | R38: בניה חדשה רוויה | S38: בנייה רוויה דיור למשתכן | W38: שגיא אלמקייס יזמות ובניה בע"מ | X38: 1197-85 | Y38: 106 | Z38: https://ashkelon.complot.co.il/newengine/Pages/request2.aspx#request/20250437
A39: 20250477 | B39: =VLOOKUP(A39,'רשימת בקשות לעבור עליהם'!$A:$A,1,0) -> 20250477 | C39: status_advanced | D39: אשקלון | E39: מתחם_78377_78375_אבן_עזרא_אשקלון | F39: מגרשים 102, 106 באבן עזרא אשקלון | G39: בניה חדשה | H39: 1197-79 , 1197-84 , 1197-85 , 1197-86 , 1197-89 , 1197-90 , 1197-98 | I39: תמל/1048+102 , תמל/1048+106 | J39: gush_helka | K39: בקשה להיתר | L39: היתר בתנאים | M39: 46329 | N39: TRUE | O39: 30/09/2025 | P39: בקשה להיתר | Q39: הרב יורם אברג'ל 35 אשקלון | R39: בניה רוייה מעל 10 קומות | S39: בנייה רוויה דיור למשתכן | T39: 104 | W39: שירז תעשיות כבלים בע"מ | X39: 1197-79 | Y39: 102 | Z39: https://ashkelon.complot.co.il/newengine/Pages/request2.aspx#request/20250477
A40: 20250514 | B40: =VLOOKUP(A40,'רשימת בקשות לעבור עליהם'!$A:$A,1,0) -> 20250514 | C40: untracked | L40: היתר | M40: 14/12/2025 | N40: TRUE | O40: 28/10/2025 | P40: בקשה להיתר | Q40: החבצלת 30 אשקלון | R40: ביטול היתר ובנייה מחדש | S40: מגורים. | W40: אביחן סידי | X40: 1960-89 | Y40: 83 | Z40: https://ashkelon.complot.co.il/newengine/Pages/request2.aspx#request/20250514
...

Sheet פרויקטים ב-status advanced שנבד
A1: מזהה הפרויקט
A2: גרופית_באגמים
A3: אגמים_אשקלון
A4: ליאם_נחמיאס_אשקלון__מתחם_1
A5: כ_כוכב_הנגב_בבלוט_ח
A6: הרב_דוד_בוזגלו_69-73-76-78_אשקלון
A7: אשקלון_מתחם_44_מגרש_305
A8: מגרש_203_214_אגמים_מזרח_אשקלון
A9: מתחם_71403_עיר_היין_אשקלון
A10: הרב_בוזגלו_דוד_69_אשקלון
A11: הרב_בוזגלו_דוד_26_אשקלון
A12: מגרש_110_אבן_עזרא_אשקלון
... A29: מגרש_125_126_עיר_היין_אשקלון

Sheet פרויקטים לעיבוי נקודתי לפי סינו
A1: מזהה פרויקט | B1: vlookup
A2: גרופית_באגמים | B2: =VLOOKUP(A2,'פרויקטים ב-status advanced שנבד'!$A:$A,1,0) -> גרופית_באגמים
A3: אסום_בשכונת_הבלוט_מגרש_3_8_אשקלון | B3: =VLOOKUP(A3,'פרויקטים ב-status advanced שנבד'!$A:$A,1,0) -> #N/A
A4: עשרת_שבטים_4_אשקלון | B4: =VLOOKUP(A4,'פרויקטים ב-status advanced שנבד'!$A:$A,1,0) -> #N/A
A5: ליאם_נחמיאס_אשקלון__מתחם_1 | B5: =VLOOKUP(A5,'פרויקטים ב-status advanced שנבד'!$A:$A,1,0) -> ליאם_נחמיאס_אשקלון__מתחם_1
A6: החלוץ_פינת_דוד_רמז_אשקלון | B6: =VLOOKUP(A6,'פרויקטים ב-status advanced שנבד'!$A:$A,1,0) -> החלוץ_פינת_דוד_רמז_אשקלון
A7: מתחם_71404_עיר_היין_אשקלון | B7: =VLOOKUP(A7,'פרויקטים ב-status advanced שנבד'!$A:$A,1,0) -> #N/A
A8: כ_כוכב_הנגב_בבלוט_ח | B8: =VLOOKUP(A8,'פרויקטים ב-status advanced שנבד'!$A:$A,1,0) -> כ_כוכב_הנגב_בבלוט_ח
A9: מתחם_71407_עיר_היין_אשקלון | B9: =VLOOKUP(A9,'פרויקטים ב-status advanced שנבד'!$A:$A,1,0) -> #N/A
A10: אגמים_אשקלון | B10: =VLOOKUP(A10,'פרויקטים ב-status advanced שנבד'!$A:$A,1,0) -> אגמים_אשקלון
A11: מתחם_71408_עיר_היין_אשקלון | B11: =VLOOKUP(A11,'פרויקטים ב-status advanced שנבד'!$A:$A,1,0) -> #N/A
A12: אשקלון_מתחם_44_מגרש_305 | B12: =VLOOKUP(A12,'פרויקטים ב-status advanced שנבד'!$A:$A,1,0) -> אשקלון_מתחם_44_מגרש_305
A13: מתחם_54242_אשקלון | B13: =VLOOKUP(A13,'פרויקטים ב-status advanced שנבד'!$A:$A,1,0) -> מתחם_54242_אשקלון
... A57: מגרש_13_בעיר_היין_אשקלון | B57: =VLOOKUP(A57,'פרויקטים ב-status advanced שנבד'!$A:$A,1,0) -> מגרש_13_בעיר_היין_אשקלון

Sheet פרויקטים חדשים שהוקמו
A1: מזהה הפרויקט
A2: דרום_אפריקה_1_אשקלון
A3: מגרש_605_בעיר_היין_אשקלון_מסחרי
